Workbook

Sheet Introduction
B2: Metadata form for the Czech NAP
B4: version 0.1
B6: https://registr.dopravniinfo.cz/cs/index.html
B8: This is a metadata form for the Czech national access point set up according to the ITS Directive and respective delegated regulations. The data owners and service providers have obligation to promote / share their data using the NAP in respective countries. Filled in details will be used to publish complete information about the data source / service.
B11: The required metadata (to be filled in) follows the CMC guidelines 2.0 laid down by the EU-EIP project (https://eip.its-platform.eu/activities/monitoring-and-harmonisation-national-access-points). In addition to that the NAP operator is asking for some detailed information not originaly covered by the CMC but necesary for the publication of the metadata at NAP. Together with the filled form the NAP operator is asking for additional data files, they are i.e. detailed documentation, samples, schema, self-certification document if the data source fall under the category of the delegated regulation, and any additional descriptive document i.e. data quality.
B14: Please fill in respective metadata for the service / data source in the list "data source form" - english and czech versions if possible (just the coloured parts). The guideline with detailed information is attached to this sheet. Filled in metadata sheet together with samples, schema and possible further documentation (in czech and english where possible) to be send to mobilitydata@rsd.cz, you will be contacted to fill in some details if necessary.

Sheet data source form - EN
B1: Metadata for dataset
B2: Please fill in respective coloured parts of the form for the service / data you are going to promote at the national access point. The metadata follows Coordinated Metadata Catalogue guidelines 2.0 of the EU-EIP project (https://eip.its-platform.eu/activities/monitoring-and-harmonisation-national-access-points), together with a Czech NAP specific details. The CMC guideline with detailed information is attached to this file. Filled in metadata sheet together with samples, schema and possible further documentation to be send to mobilitydata@rsd.cz, you will be contacted fo fill in some details if necessary. The collumn "comment" provides options for the choice fields or additional description if needed.
B5: Minimum Metadata Elements according to CMC
B7: Metadata information
B8: ref | C8: item | D8: mandatory? | E8: type | F8: fill in english | H8: comment
B9: 2.2.1.1 | C9: Metadata Date | D9: True | E9: DateTime
B10: 2.2.1.2 | C10: Metadata language | D10: True | E10: Predefined options | F10: eng | H10: Single choice: bul, gle, hrv, ita, cze, lav, dan, lit, dut, mlt, eng, pol, est, por, fin, rum, fre, slo, ger, slv, gre, spa, hun, swe
B11: 2.2.1.3 | C11: Metadata point of contact | D11: True for "name" and "email" | E11: vCard | H11: Obligation: Organisation Name and E-Mail: mandatory, other fields: optional, Type: vCard-Textfields
B12: Data source content information
A13: x | B13: 2.2.2.1 | C13: Name of dataset | D13: True | E13: Free text
A14: x | B14: 2.2.2.2 | C14: Description of dataset | D14: True | E14: Free text
A15: x | B15: 2.2.2.3 | C15: Resource Type | D15: True | E15: Predefined options | H15: Single choice: Data set, Service
A16: x | B16: 2.2.2.4 | C16: Dataset type category | D16: True | E16: Predefined options | F16: please select on the list dataset type | H16: Multiple choice: Static road network data, Static traffic signs and regulations , Toll information, Parking and rest area information, Filling and charging stations, Freight and logistics, Dynamic traffic signs and regulations , Road work, Unexpected road events and conditions, Real-time traffic data, General information for trip-planning , Public transport: location information , Public transport: operational information , Public transport: fare and purchase information , Cycle network data, Pedestrian network data, Demand-responsive modes
A17: x | B17: 2.2.2.5 | C17: Dataset detailed type | D17: False | E17: Predefined options | F17: please select on the list dataset type | H17: Multiple choice: Geometry, Road width, Number of lanes, Gradients, Junctions, Road classification, Tunnel access conditions, Bridge access conditions, Speed limits, Permanent access restrictions, Other traffic regulations, Traffic circulation plans, Location of tolling stations, Identification of tolled roads, Applicable static road user charges, Applicable variable road user charges, Payment methods for tolls, Location and conditions of parking places and service areas (general parking), Current availability of parking places (general parking), Location and conditions of parking places and service areas (truck parking), Current availability of parking places (truck parking), Park & Ride stops, Bike parking locations, Location and conditions of charging points, Location and conditions of filling stations, Availability of charging points for electric vehicles, Availability of filling stations, Freight delivery regulations, Location of delivery areas, Availability of delivery areas, Road access conditions, Lane access conditions, Bridge access conditions, Tunnel access conditions, Dynamic overtaking bans on heavy goods vehicles, Dynamic speed limits, Direction of travel on reversible lanes, Other temporary traffic management measures or plans, Long-term road works, Short-term road works, Accidents and incidents, Poor road conditions, Weather conditions affecting road surface and visibility, Traffic volume, Speed, Location and length of queues, Travel times, Waiting time at border crossings to non-EU Member States, Expected delays, Address identifiers, Topographic places, Points of interest, Parameters needed to calculate an environmental factor, Parameters such as fuel consumption needed to calculate cost, Access nodes/stop facilities: Location and features, Access nodes/stop facilities: Geometry/map layout structure, Access nodes/stop facilities: Status of features, Access nodes/stop facilities: Accessibility and paths within facility, Operational Calendar, Connection links, Network topology and routes/lines, Transport operators, Timetables (static), Timetables (real-time), estimated departure and arrival times of services, Planned interchanges between guaranteed scheduled services, Hours of operation, Vehicle details, Disruptions, delays, cancellations, Basic common standard fares, Passenger classes, Common fare products, Special Fare Products, Basic commercial conditions, Where and how to buy tickets for scheduled modes, Cycle network: geometry and lane character, Cycle network: detailed attributes, Cycle network: closures/diversions, Pedestrian network and accessibility facilities, Location of Bike sharing stations, Location of Car-sharing stations, Payment methods, Car-sharing availability, Bike sharing availability
A18: x | B18: 2.2.2.6 | C18: Service type category | D18: Only if a service is published on a NAP | F18: please select on the list dataset type | H18: Location search, Information service, Trip plans, Trip plans, auxiliary information, availability check, Trip plan computation - scheduled modes transport, Dynamic Passing times, trip plans and auxiliary information, Dynamic Information service, Dynamic availability check
A19: x | B19: 2.2.2.7 | C19: Dataset language | D19: True | E19: Predefined options | H19: Multiple choice: bul, gle, hrv, ita, cze, lav, dan, lit, dut, mlt, eng, pol, est, por, fin, rum, fre, slo, ger, slv, gre, spa, hun, swe
B20: 2.2.2.8 | C20: Georeferencing method | D20: False | E20: Predefined options
B21: Temporal information
A22: x | B22: 2.2.3.1 | C22: Valid from | D22: True | E22: DateTime
A23: x | B23: 2.2.3.2 | C23: Valid to | D23: False | E23: DateTime
B24: Geographical coverage
A25: x | B25: 2.2.4.1 | C25: Area covered by publication | D25: True | E25: Predefined options (NUTS code) | H25: Predefined NUTS 0-3; UTF8; Multiple choice; NOT NULL
A26: x | B26: 2.2.4.2 | C26: Network coverage | D26: True | E26: Predefined Text | H26: multipe choice; Motorways, Arterial road network (in the meaning of state roads or federal roads), Regional roads, Urban and local roads, Rail (long-distance or heavy-rail), Metro or light-rail network, Other public transport network, Waterways, Air network, other
B27: 2.2.4.3 | C27: Network coverage description | D27: False | E27: Free text
B28: Transportation system
A29: x | B29: 2.2.5.1 | C29: Transportation modes covered | D29: True | E29: Predefined options | H29: Multiple choice; Air, rail (including high speed rail), conventional rail, light rail, long-distance coach, maritime (including ferry), metro, tram, bus, trolley-bus, shuttle bus, shuttle ferry, taxi, car-sharing, car-pooling, car-hire, bike-sharing, bike-hire, car , truck, motorcycle, cycle, pedestrian
B30: Responsibilities
A31: x | B31: 2.2.6.1 | C31: Publisher | D31: True for "name" and "email" | E31: vCard | H31: Obligation: Organisation Name (department), E-Mail,street address, web address: mandatory, other fields: optional, Type: vCard-Textfields
B32: 2.2.6.2 | C32: Data owner | D32: True for "name" and "email"; only if "Data owner" is not equal to "Publisher" | E32: vCard | H32: Obligation: Organisation Name and E-Mail: mandatory, other fields: optional, Type: vCard-Textfields
B33: Conditions for use
A34: x | B34: 2.2.7.1 | C34: Contract or licence | D34: True | E34: Predefined options | H34: No licence – No contract, Licence and Free of charge, Licence and Fee, Contract and Free of charge, Contract and Fee, Not relevant
A35: x | B35: 2.2.7.2 | C35: Condition for use | D35: True if "Contract or licence" is used | E35: Free text
B36: Access information
A37: x | B37: 2.2.8.1 | C37: Data Format- Encoding | D37: False | E37: Predefined options | H37: ASCII, UTF-8, UTF-16, ISO-8859-1, ISO-8859-15, other
A38: x | B38: 2.2.8.2 | C38: Data Format- Syntax | D38: True | E38: Predefined options | H38: XML, JSON, CSV, ASN.1 encoding rules, Protocol buffers, Other
A39: x | B39: 2.2.8.3 | C39: Data Format- Grammar | D39: False | E39: Predefined options | H39: XSD, JSON Schema, ASN.1, Protocol buffers, other
A40: x | B40: 2.2.8.4 | C40: Data Format- Data Model | D40: True | E40: Predefined options | H40: DATEX II profile, OCIT-C, DATEX II Light, NeTEx (CEN/TS 16614), SIRI (CEN/TS 15531), GFTS, VDV Stadard (VDV 452, 455, 462, ...), IFOPT, ETSI / ISO Model (DENM, CAM, SPAT/MAP, IVI, …), tpegML Model (TPEG2-TEC, TPEG2-PKI, ...), KML, MPEG-4, MDM-Container, DINO, OpenAPI, other
A41: x | B41: 2.2.8.5 | C41: Data format description | D41: False | E41: Free text (200) | H41: describe version, profile and possible extension to the model
A42: x | B42: 2.2.8.6 | C42: Access interface / application layer protocol | D42: True | E42: Predefined options | H42: SOAP, OTS2, HTTP/HTTPS, FTP, RSS, AMQP, MQTT, gRPC, other
A43: x | B43: 2.2.8.7 | C43: Communication method | D43: True | E43: Predefined options | H43: Push, Push on occurrence, Pull
...

Sheet lists
A1: 2.2.1.2 | B1: 2.2.2.3
A2: bul | B2: Data set | C2: Static road network data | D2: Geometry | E2: Location search
A3: gle | B3: Service | C3: Static traffic signs and regulations | D3: Road width | E3: Information service
A4: hrv | C4: Toll information | D4: Number of lanes | E4: Trip plans
A5: ita | C5: Parking and rest area information | D5: Gradients | E5: Trip plans
A6: cze | C6: Filling and charging stations | D6: Junctions | E6: auxiliary information
A7: lav | C7: Freight and logistics | D7: Road classification | E7: availability check
A8: dan | C8: Dynamic traffic signs and regulations | D8: Tunnel access conditions | E8: Trip plan computation - scheduled modes transport
A9: lit | C9: Road work | D9: Bridge access conditions | E9: Dynamic Passing times
A10: dut | C10: Unexpected road events and conditions | D10: Speed limits | E10: trip plans and auxiliary information
A11: mlt | C11: Real-time traffic data | D11: Permanent access restrictions | E11: Dynamic Information service
A12: eng | C12: General information for trip-planning | D12: Other traffic regulations | E12: Dynamic availability check
A13: pol | C13: Public transport: location information | D13: Traffic circulation plans
A14: est | C14: Public transport: operational information | D14: Location of tolling stations
A15: por | C15: Public transport: fare and purchase information | D15: Identification of tolled roads
A16: fin | C16: Cycle network data | D16: Applicable static road user charges
A17: rum | C17: Pedestrian network data | D17: Applicable variable road user charges
A18: fre | C18: Demand-responsive modes | D18: Payment methods for tolls
A19: slo | D19: Location and conditions of parking places and service areas (general parking)
A20: ger | D20: Current availability of parking places (general parking)
A21: slv | D21: Location and conditions of parking places and service areas (truck parking)
A22: gre | D22: Current availability of parking places (truck parking)
A23: spa | D23: Park & Ride stops
A24: hun | D24: Bike parking locations
A25: swe | D25: Location and conditions of charging points
D26: Location and conditions of filling stations
D27: Availability of charging points for electric vehicles
D28: Availability of filling stations
D29: Freight delivery regulations
D30: Location of delivery areas
D31: Availability of delivery areas
D32: Road access conditions
D33: Lane access conditions
D34: Bridge access conditions
D35: Tunnel access conditions
D36: Dynamic overtaking bans on heavy goods vehicles
D37: Dynamic speed limits
... D87: Bike sharing availability

Sheet data source form - CZ
B1: Meta data datové sady
B2: Vyplňte příslušná metadata (pouze podbarvené části) pro službu / data, která hodláte propagovat prostřednictvím národního přístupového místa. Metadata se řídí pokyny z koordinovaného katalogu metadat 2.0 projektu EU-EIP (https://eip.its-platform.eu/activities/monitoring-and-harmonisation-national-access-points). Kde je možnost výběru z možností tak vyplňujte v angličtině, možnosti jsou zmíněny ve sloupci komentář. Popis s podrobnými informacemi je připojen k tomuto souboru. Vyplněný list metadat spolu se vzorky, schématem a případnou další dokumentací zašlete na mobildata@rsd.cz, budete případně kontaktováni pro vyplnění některých podrobností a domluvební dalšího postupu.
B5: Minimum Metadata Elements according to CMC
B7: Metadata information
B8: ref | C8: item | D8: mandatory? | E8: type | F8: vyplňte česky (pouze volná textová pole) | H8: comment
B9: 2.2.1.1 | C9: Metadata Date | D9: True | E9: DateTime | F9: ='data source form - EN'!F9 -> 0
B10: 2.2.1.2 | C10: Metadata language | D10: True | E10: Predefined options | F10: cze | H10: Single choice: bul, gle, hrv, ita, cze, lav, dan, lit, dut, mlt, eng, pol, est, por, fin, rum, fre, slo, ger, slv, gre, spa, hun, swe
B11: 2.2.1.3 | C11: Metadata point of contact | D11: True for "name" and "email" | E11: vCard | F11: ='data source form - EN'!F11 -> 0 | H11: Obligation: Organisation Name and E-Mail: mandatory, other fields: optional, Type: vCard-Textfields
B12: Data source content information
B13: 2.2.2.1 | C13: Name of dataset | D13: True | E13: Free text
B14: 2.2.2.2 | C14: Description of dataset | D14: True | E14: Free text
B15: 2.2.2.3 | C15: Resource Type | D15: True | E15: Predefined options | F15: ='data source form - EN'!F15 -> 0 | H15: Single choice: Data set, Service
B16: 2.2.2.4 | C16: Dataset type category | D16: True | E16: Predefined options | F16: ='data source form - EN'!F16 -> please select on the list dataset type | H16: Multiple choice: Static road network data, Static traffic signs and regulations , Toll information, Parking and rest area information, Filling and charging stations, Freight and logistics, Dynamic traffic signs and regulations , Road work, Unexpected road events and conditions, Real-time traffic data, General information for trip-planning , Public transport: location information , Public transport: operational information , Public transport: fare and purchase information , Cycle network data, Pedestrian network data, Demand-responsive modes
B17: 2.2.2.5 | C17: Dataset detailed type | D17: False | E17: Predefined options | F17: ='data source form - EN'!F17 -> please select on the list dataset type | H17: Multiple choice: Geometry, Road width, Number of lanes, Gradients, Junctions, Road classification, Tunnel access conditions, Bridge access conditions, Speed limits, Permanent access restrictions, Other traffic regulations, Traffic circulation plans, Location of tolling stations, Identification of tolled roads, Applicable static road user charges, Applicable variable road user charges, Payment methods for tolls, Location and conditions of parking places and service areas (general parking), Current availability of parking places (general parking), Location and conditions of parking places and service areas (truck parking), Current availability of parking places (truck parking), Park & Ride stops, Bike parking locations, Location and conditions of charging points, Location and conditions of filling stations, Availability of charging points for electric vehicles, Availability of filling stations, Freight delivery regulations, Location of delivery areas, Availability of delivery areas, Road access conditions, Lane access conditions, Bridge access conditions, Tunnel access conditions, Dynamic overtaking bans on heavy goods vehicles, Dynamic speed limits, Direction of travel on reversible lanes, Other temporary traffic management measures or plans, Long-term road works, Short-term road works, Accidents and incidents, Poor road conditions, Weather conditions affecting road surface and visibility, Traffic volume, Speed, Location and length of queues, Travel times, Waiting time at border crossings to non-EU Member States, Expected delays, Address identifiers, Topographic places, Points of interest, Parameters needed to calculate an environmental factor, Parameters such as fuel consumption needed to calculate cost, Access nodes/stop facilities: Location and features, Access nodes/stop facilities: Geometry/map layout structure, Access nodes/stop facilities: Status of features, Access nodes/stop facilities: Accessibility and paths within facility, Operational Calendar, Connection links, Network topology and routes/lines, Transport operators, Timetables (static), Timetables (real-time), estimated departure and arrival times of services, Planned interchanges between guaranteed scheduled services, Hours of operation, Vehicle details, Disruptions, delays, cancellations, Basic common standard fares, Passenger classes, Common fare products, Special Fare Products, Basic commercial conditions, Where and how to buy tickets for scheduled modes, Cycle network: geometry and lane character, Cycle network: detailed attributes, Cycle network: closures/diversions, Pedestrian network and accessibility facilities, Location of Bike sharing stations, Location of Car-sharing stations, Payment methods, Car-sharing availability, Bike sharing availability
B18: 2.2.2.6 | C18: Service type category | D18: Only if a service is published on a NAP | F18: ='data source form - EN'!F18 -> please select on the list dataset type | H18: Location search, Information service, Trip plans, Trip plans, auxiliary information, availability check, Trip plan computation - scheduled modes transport, Dynamic Passing times, trip plans and auxiliary information, Dynamic Information service, Dynamic availability check
B19: 2.2.2.7 | C19: Dataset language | D19: True | E19: Predefined options | F19: ='data source form - EN'!F19 -> 0 | H19: Multiple choice: bul, gle, hrv, ita, cze, lav, dan, lit, dut, mlt, eng, pol, est, por, fin, rum, fre, slo, ger, slv, gre, spa, hun, swe
B20: 2.2.2.8 | C20: Georeferencing method | D20: False | E20: Predefined options | F20: ='data source form - EN'!F20 -> 0
B21: Temporal information
B22: 2.2.3.1 | C22: Valid from | D22: True | E22: DateTime | F22: ='data source form - EN'!F22 -> 0
B23: 2.2.3.2 | C23: Valid to | D23: False | E23: DateTime | F23: ='data source form - EN'!F23 -> 0
B24: Geographical coverage
B25: 2.2.4.1 | C25: Area covered by publication | D25: True | E25: Predefined options (NUTS code) | F25: ='data source form - EN'!F25 -> 0 | H25: Predefined NUTS 0-3; UTF8; Multiple choice; NOT NULL
B26: 2.2.4.2 | C26: Network coverage | D26: True | E26: Predefined Text | F26: ='data source form - EN'!F26 -> 0 | H26: multipe choice; Motorways, Arterial road network (in the meaning of state roads or federal roads), Regional roads, Urban and local roads, Rail (long-distance or heavy-rail), Metro or light-rail network, Other public transport network, Waterways, Air network, other
B27: 2.2.4.3 | C27: Network coverage description | D27: False | E27: Free text
B28: Transportation system
B29: 2.2.5.1 | C29: Transportation modes covered | D29: True | E29: Predefined options | F29: ='data source form - EN'!F29 -> 0 | H29: Multiple choice; Air, rail (including high speed rail), conventional rail, light rail, long-distance coach, maritime (including ferry), metro, tram, bus, trolley-bus, shuttle bus, shuttle ferry, taxi, car-sharing, car-pooling, car-hire, bike-sharing, bike-hire, car , truck, motorcycle, cycle, pedestrian
B30: Responsibilities
B31: 2.2.6.1 | C31: Publisher | D31: True for "name" and "email" | E31: vCard | F31: ='data source form - EN'!F31 -> 0 | H31: Obligation: Organisation Name and E-Mail: mandatory, other fields: optional, Type: vCard-Textfields
B32: 2.2.6.2 | C32: Data owner | D32: True for "name" and "email"; only if "Data owner" is not equal to "Publisher" | E32: vCard | F32: ='data source form - EN'!F32 -> 0 | H32: Obligation: Organisation Name and E-Mail: mandatory, other fields: optional, Type: vCard-Textfields
B33: Conditions for use
B34: 2.2.7.1 | C34: Contract or licence | D34: True | E34: Predefined options | F34: ='data source form - EN'!F34 -> 0 | H34: No licence – No contract, Licence and Free of charge, Licence and Fee, Contract and Free of charge, Contract and Fee, Not relevant
B35: 2.2.7.2 | C35: Condition for use | D35: True if "Contract or licence" is used | E35: Free text
B36: Access information
B37: 2.2.8.1 | C37: Data Format- Encoding | D37: False | E37: Predefined options | F37: ='data source form - EN'!F37 -> 0 | H37: ASCII, UTF-8, UTF-16, ISO-8859-1, ISO-8859-15, other
B38: 2.2.8.2 | C38: Data Format- Syntax | D38: True | E38: Predefined options | F38: ='data source form - EN'!F38 -> 0 | H38: XML, JSON, CSV, ASN.1 encoding rules, Protocol buffers, Other
B39: 2.2.8.3 | C39: Data Format- Grammar | D39: False | E39: Predefined options | F39: ='data source form - EN'!F39 -> 0 | H39: XSD, JSON Schema, ASN.1, Protocol buffers, other
B40: 2.2.8.4 | C40: Data Format- Data Model | D40: True | E40: Predefined options | F40: ='data source form - EN'!F40 -> 0 | H40: DATEX II profile, OCIT-C, DATEX II Light, NeTEx (CEN/TS 16614), SIRI (CEN/TS 15531), GFTS, VDV Stadard (VDV 452, 455, 462, ...), IFOPT, ETSI / ISO Model (DENM, CAM, SPAT/MAP, IVI, …), tpegML Model (TPEG2-TEC, TPEG2-PKI, ...), KML, MPEG-4, MDM-Container, DINO, OpenAPI, other
B41: 2.2.8.5 | C41: Data format description | D41: False | E41: Free text (200) | H41: describe version, profile and possible extension to the model
B42: 2.2.8.6 | C42: Access interface / application layer protocol | D42: True | E42: Predefined options | F42: ='data source form - EN'!F42 -> 0 | H42: SOAP, OTS2, HTTP/HTTPS, FTP, RSS, AMQP, MQTT, gRPC, other
B43: 2.2.8.7 | C43: Communication method | D43: True | E43: Predefined options | F43: ='data source form - EN'!F43 -> 0 | H43: Push, Push on occurrence, Pull
...

Sheet dataset type
A1: Please select (x) category and detailed type of your dataset (tick yelow collored parts)
B2: Options for Metadata element "Dataset type category" | C2: sel | D2: Options for Metadata element "Dataset detailed type" | E2: Coded reference to data category of EC Del. Reg. * | F2: * Explanation
A4: x | B4: Static road network data | C4: x | D4: Geometry | E4: B-1 a i, A-1.1.e.i | F4: A= Priority Action A, Commission Delegated Regulation (EU) 2017/1926 of 31 May 2017 supplementing Directive 2010/40/EU of the European Parliament and of the Council with regard to the provision of EU-wide multimodal travel information services
C5: x | D5: Road width | E5: B-1 a ii, A-1.1.e.i | F5: B= Priority Action B, Commission Delegated Regulation (EU) 2015/962 of 18 December 2014 supplementing Directive 2010/40/EU of the European Parliament and of the Council with regard to the provision of EU-wide real-time traffic information services
C6: x | D6: Number of lanes | E6: B-1 a ii, A-1.1.e.i | F6: C= Priority Action C,Commission Delegated Regulation (EU) No 886/2013 of 15 May 2013 supplementing Directive 2010/40/EU of the European Parliament and of the Council with regard to data and procedures for the provision, where possible, of road safety-related minimum universal traffic information free of charge to users
D7: Gradients | E7: B-1 a iv, A-1.1.e.i | F7: E= Priority Action E, Commission Delegated Regulation (EU) No 885/2013 of 15 May 2013 supplementing ITS Directive 2010/40/EU of the European Parliament and of the Council with regard to the provision of information services for safe and secure parking places for trucks and commercial vehicles
D8: Junctions | E8: B-1 a v, A-1.1.e.i | F8: n/a = not considered by Del. Regs.; added for completeness
D9: Road classification | E9: B-1 b, A-1.1.e.i
A10: x | B10: Static traffic signs and regulations | D10: Tunnel access conditions | E10: B-1 c i
D11: Bridge access conditions | E11: B-1 c ii
D12: Speed limits | E12: B-1 d
D13: Other static traffic signs | E13: n/a
D14: Permanent access restrictions | E14: B-1 c iii
D15: Other traffic regulations | E15: B-1 c iv
C16: x | D16: Traffic circulation plans | E16: B-1 e
A17: x | B17: Toll information | D17: Location of tolling stations | E17: B-1 g
C18: x | D18: Identification of tolled roads | E18: B-1 h
D19: Applicable road user charges and payment methods | E19: B-1 h, B-2 k, A-2.2.c.ii
D20: Payment methods for tolls | E20: A-1.3.b.i
B21: Parking and rest area information | D21: General Parking: Location and conditions of parking places and service areas | E21: B-1 i, B-2 n, A-1.2.b, A-1.3.b.iii
D22: General Parking: Current availability of parking places | E22: B-2 l, A-2.2.c.ii
D23: Truck Parking: Location and conditions of parking places and service areas | E23: E
D24: Truck Parking: Current availability of parking places | E24: E
D25: Park & Ride stops | E25: A-1.2.a.i
D26: Bike parking locations | E26: A-1.2.a.v
B27: Filling and charging stations | D27: Location and conditions of charging points | E27: B-1 j, A-1.2.a.iv, A-1.3.b.iii
D28: Location and conditions of filling stations | E28: B-1 k, A-1.2.a.iv, A-1.3.b.iii
D29: Availability of charging points for electric vehicles | E29: B-2 o, A-2.2.b
D30: Availability of filling stations | E30: A-2.2.b
B31: Freight and logistics | D31: Freight delivery regulations | E31: B-1 f
D32: Location of delivery areas | E32: B-1 m
D33: Availability of delivery areas | E33: B-2 m
B34: Dynamic traffic signs and regulations | D34: Closures and dynamic access conditions of roads | E34: B-2 a
D35: Closures and dynamic access conditions of lanes | E35: B-2 b
D36: Closures and dynamic access conditions of bridges | E36: B-2 c
D37: Closures and dynamic access conditions of tunnels | E37: n/a
D38: Other access restrictions and traffic regulations | E38: n/a
D39: Dynamic overtaking bans on heavy goods vehicles | E39: B-2 d
D40: Dynamic speed limits | E40: B-2 g
D41: Direction of travel on reversible lanes | E41: B-2 h
...
